Workbook

Sheet Cover
A1: PROJECT FINANCE MODEL — SOLAR IPP
A2: Solar Ipp Karnataka 100Mw
A4: KEY PERFORMANCE INDICATORS
A5: Equity IRR | B5: 0.026700164
A6: Project IRR | B6: 0.057218072
A7: Min DSCR | B7: 0.84987987
A8: Avg DSCR | B8: 1.1216402
A9: LLCR | B9: 0.99726596
A10: PLCR | B10: 1.076737
A11: NPV Equity (INR Lakhs) | B11: -11540.737
A12: Peak Debt (INR Lakhs) | B12: 31500
A13: Debt Payback (years) | B13: 18
A15: PROJECT PARAMETERS
A16: Model ID | B16: solar_ipp_karnataka_100mw
A17: Project Type | B17: solar_ipp
A18: Currency | B18: INR Lakhs
A19: Periods per Year | B19: 4
A20: Construction Periods | B20: 4
A21: Operations Periods | B21: 100
A22: Total Periods | B22: 104
A23: COD Period | B23: 4
A24: Debt Maturity Period | B24: 75
A25: Report Date | B25: 28-Mar-2026
A27: KEY ASSUMPTIONS
A28: Installed Capacity | B28: 100 | C28: MW
A29: CUF (P50) | B29: 0.22 | C29: ratio
A30: Degradation Rate (p.a.) | B30: 0.005 | C30: per year
A31: PPA Tariff | B31: 2.65 | C31: INR/kWh
A32: Tariff Escalation | B32: 0 | C32: p.a.
A33: Capex per MW | B33: 450 | C33: INR Lakh/MW
A34: Total Capex | B34: 45000 | C34: INR Lakhs
A35: Debt % | B35: 0.7 | C35: ratio
A36: Interest Rate | B36: 0.0975 | C36: p.a.
A37: Debt Tenor | B37: 17.75 | C37: years
A38: Moratorium Periods | B38: 0 | C38: quarters
A39: DSCR Target | B39: 1.2 | C39: x
... A41: Tax Rate | B41: 0.25 | C41: effective
A42: Depreciation Method | B42: slm
A43: Equity IRR Target | B43: 0.14 | C43: hurdle
A45: SCENARIO SUMMARY
...

Sheet Income Statement
A1: INCOME STATEMENT
A2: Line Item | B2: Unit | C2: Q1 CON | D2: Q2 CON | E2: Q3 CON | F2: Q4 CON | G2: Q1 OPS | H2: Q2 OPS | I2: Q3 OPS | J2: Q4 OPS | K2: Q5 OPS | L2: Q6 OPS | M2: Q7 OPS | N2: Q8 OPS | O2: Q9 OPS | P2: Q10 OPS | Q2: Q11 OPS | R2: Q12 OPS | S2: Q13 OPS | T2: Q14 OPS | U2: Q15 OPS | V2: Q16 OPS | W2: Q17 OPS | X2: Q18 OPS | Y2: Q19 OPS | Z2: Q20 OPS | AA2: Q21 OPS | AB2: Q22 OPS | AC2: Q23 OPS | AD2: Q24 OPS | AE2: Q25 OPS | AF2: Q26 OPS | AG2: Q27 OPS | AH2: Q28 OPS | AI2: Q29 OPS | AJ2: Q30 OPS | AK2: Q31 OPS | AL2: Q32 OPS | AM2: Q33 OPS | AN2: Q34 OPS | AO2: Q35 OPS | AP2: Q36 OPS | AQ2: Q37 OPS | AR2: Q38 OPS | AS2: Q39 OPS | AT2: Q40 OPS | AU2: Q41 OPS | AV2: Q42 OPS | AW2: Q43 OPS | AX2: Q44 OPS | AY2: Q45 OPS | AZ2: Q46 OPS | BA2: Q47 OPS | BB2: Q48 OPS | BC2: Q49 OPS | BD2: Q50 OPS | BE2: Q51 OPS | BF2: Q52 OPS | BG2: Q53 OPS | BH2: Q54 OPS | BI2: Q55 OPS | BJ2: Q56 OPS | BK2: Q57 OPS | BL2: Q58 OPS | BM2: Q59 OPS | BN2: Q60 OPS | BO2: Q61 OPS | BP2: Q62 OPS | BQ2: Q63 OPS | BR2: Q64 OPS | BS2: Q65 OPS | BT2: Q66 OPS | BU2: Q67 OPS | BV2: Q68 OPS | BW2: Q69 OPS | BX2: Q70 OPS | BY2: Q71 OPS | BZ2: Q72 OPS | CA2: Q73 OPS | CB2: Q74 OPS | CC2: Q75 OPS | CD2: Q76 OPS | CE2: Q77 OPS | CF2: Q78 OPS | CG2: Q79 OPS | CH2: Q80 OPS | CI2: Q81 OPS | CJ2: Q82 OPS | CK2: Q83 OPS | CL2: Q84 OPS | CM2: Q85 OPS | CN2: Q86 OPS | CO2: Q87 OPS | CP2: Q88 OPS | CQ2: Q89 OPS | CR2: Q90 OPS | CS2: Q91 OPS | CT2: Q92 OPS | CU2: Q93 OPS | CV2: Q94 OPS | CW2: Q95 OPS | CX2: Q96 OPS | CY2: Q97 OPS | CZ2: Q98 OPS | DA2: Q99 OPS | DB2: Q100 OPS
A3: REVENUE
A4: Net Generation | B4: kWh | C4: 0 | D4: 0 | E4: 0 | F4: 0 | G4: 47699404 | H4: 47639668 | I4: 47580007 | J4: 47520420 | K4: 47460907 | L4: 47401470 | M4: 47342107 | N4: 47282818 | O4: 47223603 | P4: 47164462 | Q4: 47105396 | R4: 47046404 | S4: 46987485 | T4: 46928640 | U4: 46869869 | V4: 46811171 | W4: 46752548 | X4: 46693997 | Y4: 46635520 | Z4: 46577116 | AA4: 46518785 | AB4: 46460527 | AC4: 46402342 | AD4: 46344230 | AE4: 46286191 | AF4: 46228224 | AG4: 46170330 | AH4: 46112509 | AI4: 46054760 | AJ4: 45997083 | AK4: 45939479 | AL4: 45881946 | AM4: 45824486 | AN4: 45767098 | AO4: 45709781 | AP4: 45652537 | AQ4: 45595364 | AR4: 45538262 | AS4: 45481232 | AT4: 45424274 | AU4: 45367387 | AV4: 45310571 | AW4: 45253826 | AX4: 45197153 | AY4: 45140550 | AZ4: 45084018 | BA4: 45027557 | BB4: 44971167 | BC4: 44914847 | BD4: 44858598 | BE4: 44802419 | BF4: 44746311 | BG4: 44690273 | BH4: 44634305 | BI4: 44578407 | BJ4: 44522579 | BK4: 44466822 | BL4: 44411134 | BM4: 44355515 | BN4: 44299967 | BO4: 44244487 | BP4: 44189078 | BQ4: 44133738 | BR4: 44078467 | BS4: 44023265 | BT4: 43968132 | BU4: 43913069 | BV4: 43858074 | BW4: 43803149 | BX4: 43748292 | BY4: 43693504 | BZ4: 43638784 | CA4: 43584133 | CB4: 43529550 | CC4: 43475036 | CD4: 43420590 | CE4: 43366212 | CF4: 43311903 | CG4: 43257661 | CH4: 43203487 | CI4: 43149381 | CJ4: 43095343 | CK4: 43041373 | CL4: 42987470 | CM4: 42933634 | CN4: 42879866 | CO4: 42826166 | CP4: 42772532 | CQ4: 42718966 | CR4: 42665467 | CS4: 42612035 | CT4: 42558670 | CU4: 42505371 | CV4: 42452140 | CW4: 42398975 | CX4: 42345876 | CY4: 42292844 | CZ4: 42239879 | DA4: 42186980 | DB4: 42134147
A5: PPA Revenue | B5: INR Lakhs | C5: 0 | D5: 0 | E5: 0 | F5: 0 | G5: 1264.0342 | H5: 1262.4512 | I5: 1260.8702 | J5: 1259.2911 | K5: 1257.714 | L5: 1256.1389 | M5: 1254.5658 | N5: 1252.9947 | O5: 1251.4255 | P5: 1249.8583 | Q5: 1248.293 | R5: 1246.7297 | S5: 1245.1684 | T5: 1243.609 | U5: 1242.0515 | V5: 1240.496 | W5: 1238.9425 | X5: 1237.3909 | Y5: 1235.8413 | Z5: 1234.2936 | AA5: 1232.7478 | AB5: 1231.204 | AC5: 1229.6621 | AD5: 1228.1221 | AE5: 1226.5841 | AF5: 1225.0479 | AG5: 1223.5138 | AH5: 1221.9815 | AI5: 1220.4511 | AJ5: 1218.9227 | AK5: 1217.3962 | AL5: 1215.8716 | AM5: 1214.3489 | AN5: 1212.8281 | AO5: 1211.3092 | AP5: 1209.7922 | AQ5: 1208.2771 | AR5: 1206.764 | AS5: 1205.2527 | AT5: 1203.7433 | AU5: 1202.2358 | AV5: 1200.7301 | AW5: 1199.2264 | AX5: 1197.7245 | AY5: 1196.2246 | AZ5: 1194.7265 | BA5: 1193.2303 | BB5: 1191.7359 | BC5: 1190.2434 | BD5: 1188.7528 | BE5: 1187.2641 | BF5: 1185.7772 | BG5: 1184.2922 | BH5: 1182.8091 | BI5: 1181.3278 | BJ5: 1179.8484 | BK5: 1178.3708 | BL5: 1176.895 | BM5: 1175.4212 | BN5: 1173.9491 | BO5: 1172.4789 | BP5: 1171.0106 | BQ5: 1169.544 | BR5: 1168.0794 | BS5: 1166.6165 | BT5: 1165.1555 | BU5: 1163.6963 | BV5: 1162.239 | BW5: 1160.7834 | BX5: 1159.3297 | BY5: 1157.8778 | BZ5: 1156.4278 | CA5: 1154.9795 | CB5: 1153.5331 | CC5: 1152.0885 | CD5: 1150.6456 | CE5: 1149.2046 | CF5: 1147.7654 | CG5: 1146.328 | CH5: 1144.8924 | CI5: 1143.4586 | CJ5: 1142.0266 | CK5: 1140.5964 | CL5: 1139.1679 | CM5: 1137.7413 | CN5: 1136.3165 | CO5: 1134.8934 | CP5: 1133.4721 | CQ5: 1132.0526 | CR5: 1130.6349 | CS5: 1129.2189 | CT5: 1127.8047 | CU5: 1126.3923 | CV5: 1124.9817 | CW5: 1123.5728 | CX5: 1122.1657 | CY5: 1120.7604 | CZ5: 1119.3568 | DA5: 1117.955 | DB5: 1116.5549
A7: OPERATING COSTS
A8: Base O&M | B8: INR Lakhs | C8: 0 | D8: 0 | E8: 0 | F8: 0 | G8: 206 | H8: 207.52792 | I8: 209.06717 | J8: 210.61783 | K8: 212.18 | L8: 213.75375 | M8: 215.33918 | N8: 216.93637 | O8: 218.5454 | P8: 220.16637 | Q8: 221.79936 | R8: 223.44446 | S8: 225.10176 | T8: 226.77136 | U8: 228.45334 | V8: 230.14779 | W8: 231.85481 | X8: 233.5745 | Y8: 235.30694 | Z8: 237.05223 | AA8: 238.81046 | AB8: 240.58173 | AC8: 242.36615 | AD8: 244.16379 | AE8: 245.97477 | AF8: 247.79919 | AG8: 249.63713 | AH8: 251.48871 | AI8: 253.35402 | AJ8: 255.23316 | AK8: 257.12624 | AL8: 259.03337 | AM8: 260.95464 | AN8: 262.89016 | AO8: 264.84003 | AP8: 266.80437 | AQ8: 268.78328 | AR8: 270.77686 | AS8: 272.78523 | AT8: 274.8085 | AU8: 276.84677 | AV8: 278.90017 | AW8: 280.96879 | AX8: 283.05275 | AY8: 285.15218 | AZ8: 287.26717 | BA8: 289.39785 | BB8: 291.54434 | BC8: 293.70674 | BD8: 295.88519 | BE8: 298.07979 | BF8: 300.29067 | BG8: 302.51794 | BH8: 304.76174 | BI8: 307.02218 | BJ8: 309.29939 | BK8: 311.59348 | BL8: 313.90459 | BM8: 316.23285 | BN8: 318.57837 | BO8: 320.94129 | BP8: 323.32173 | BQ8: 325.71983 | BR8: 328.13572 | BS8: 330.56953 | BT8: 333.02138 | BU8: 335.49143 | BV8: 337.97979 | BW8: 340.48661 | BX8: 343.01203 | BY8: 345.55617 | BZ8: 348.11919 | CA8: 350.70121 | CB8: 353.30239 | CC8: 355.92286 | CD8: 358.56276 | CE8: 361.22225 | CF8: 363.90146 | CG8: 366.60054 | CH8: 369.31964 | CI8: 372.05891 | CJ8: 374.8185 | CK8: 377.59856 | CL8: 380.39923 | CM8: 383.22068 | CN8: 386.06306 | CO8: 388.92651 | CP8: 391.81121 | CQ8: 394.7173 | CR8: 397.64495 | CS8: 400.59431 | CT8: 403.56555 | CU8: 406.55882 | CV8: 409.5743 | CW8: 412.61214 | CX8: 415.67251 | CY8: 418.75559 | CZ8: 421.86153 | DA8: 424.9905 | DB8: 428.14269
A9: Insurance | B9: INR Lakhs | C9: 0 | D9: 0 | E9: 0 | F9: 0 | G9: 56.25 | H9: 56.25 | I9: 56.25 | J9: 56.25 | K9: 56.25 | L9: 56.25 | M9: 56.25 | N9: 56.25 | O9: 56.25 | P9: 56.25 | Q9: 56.25 | R9: 56.25 | S9: 56.25 | T9: 56.25 | U9: 56.25 | V9: 56.25 | W9: 56.25 | X9: 56.25 | Y9: 56.25 | Z9: 56.25 | AA9: 56.25 | AB9: 56.25 | AC9: 56.25 | AD9: 56.25 | AE9: 56.25 | AF9: 56.25 | AG9: 56.25 | AH9: 56.25 | AI9: 56.25 | AJ9: 56.25 | AK9: 56.25 | AL9: 56.25 | AM9: 56.25 | AN9: 56.25 | AO9: 56.25 | AP9: 56.25 | AQ9: 56.25 | AR9: 56.25 | AS9: 56.25 | AT9: 56.25 | AU9: 56.25 | AV9: 56.25 | AW9: 56.25 | AX9: 56.25 | AY9: 56.25 | AZ9: 56.25 | BA9: 56.25 | BB9: 56.25 | BC9: 56.25 | BD9: 56.25 | BE9: 56.25 | BF9: 56.25 | BG9: 56.25 | BH9: 56.25 | BI9: 56.25 | BJ9: 56.25 | BK9: 56.25 | BL9: 56.25 | BM9: 56.25 | BN9: 56.25 | BO9: 56.25 | BP9: 56.25 | BQ9: 56.25 | BR9: 56.25 | BS9: 56.25 | BT9: 56.25 | BU9: 56.25 | BV9: 56.25 | BW9: 56.25 | BX9: 56.25 | BY9: 56.25 | BZ9: 56.25 | CA9: 56.25 | CB9: 56.25 | CC9: 56.25 | CD9: 56.25 | CE9: 56.25 | CF9: 56.25 | CG9: 56.25 | CH9: 56.25 | CI9: 56.25 | CJ9: 56.25 | CK9: 56.25 | CL9: 56.25 | CM9: 56.25 | CN9: 56.25 | CO9: 56.25 | CP9: 56.25 | CQ9: 56.25 | CR9: 56.25 | CS9: 56.25 | CT9: 56.25 | CU9: 56.25 | CV9: 56.25 | CW9: 56.25 | CX9: 56.25 | CY9: 56.25 | CZ9: 56.25 | DA9: 56.25 | DB9: 56.25
A10: Land Lease | B10: INR Lakhs | C10: 0 | D10: 0 | E10: 0 | F10: 0 | G10: 0 | H10: 0 | I10: 0 | J10: 0 | K10: 0 | L10: 0 | M10: 0 | N10: 0 | O10: 0 | P10: 0 | Q10: 0 | R10: 0 | S10: 0 | T10: 0 | U10: 0 | V10: 0 | W10: 0 | X10: 0 | Y10: 0 | Z10: 0 | AA10: 0 | AB10: 0 | AC10: 0 | AD10: 0 | AE10: 0 | AF10: 0 | AG10: 0 | AH10: 0 | AI10: 0 | AJ10: 0 | AK10: 0 | AL10: 0 | AM10: 0 | AN10: 0 | AO10: 0 | AP10: 0 | AQ10: 0 | AR10: 0 | AS10: 0 | AT10: 0 | AU10: 0 | AV10: 0 | AW10: 0 | AX10: 0 | AY10: 0 | AZ10: 0 | BA10: 0 | BB10: 0 | BC10: 0 | BD10: 0 | BE10: 0 | BF10: 0 | BG10: 0 | BH10: 0 | BI10: 0 | BJ10: 0 | BK10: 0 | BL10: 0 | BM10: 0 | BN10: 0 | BO10: 0 | BP10: 0 | BQ10: 0 | BR10: 0 | BS10: 0 | BT10: 0 | BU10: 0 | BV10: 0 | BW10: 0 | BX10: 0 | BY10: 0 | BZ10: 0 | CA10: 0 | CB10: 0 | CC10: 0 | CD10: 0 | CE10: 0 | CF10: 0 | CG10: 0 | CH10: 0 | CI10: 0 | CJ10: 0 | CK10: 0 | CL10: 0 | CM10: 0 | CN10: 0 | CO10: 0 | CP10: 0 | CQ10: 0 | CR10: 0 | CS10: 0 | CT10: 0 | CU10: 0 | CV10: 0 | CW10: 0 | CX10: 0 | CY10: 0 | CZ10: 0 | DA10: 0 | DB10: 0
A11: Total OPEX | B11: INR Lakhs | C11: 0 | D11: 0 | E11: 0 | F11: 0 | G11: 262.25 | H11: 263.77792 | I11: 265.31717 | J11: 266.86783 | K11: 268.43 | L11: 270.00375 | M11: 271.58918 | N11: 273.18637 | O11: 274.7954 | P11: 276.41637 | Q11: 278.04936 | R11: 279.69446 | S11: 281.35176 | T11: 283.02136 | U11: 284.70334 | V11: 286.39779 | W11: 288.10481 | X11: 289.8245 | Y11: 291.55694 | Z11: 293.30223 | AA11: 295.06046 | AB11: 296.83173 | AC11: 298.61615 | AD11: 300.41379 | AE11: 302.22477 | AF11: 304.04919 | AG11: 305.88713 | AH11: 307.73871 | AI11: 309.60402 | AJ11: 311.48316 | AK11: 313.37624 | AL11: 315.28337 | AM11: 317.20464 | AN11: 319.14016 | AO11: 321.09003 | AP11: 323.05437 | AQ11: 325.03328 | AR11: 327.02686 | AS11: 329.03523 | AT11: 331.0585 | AU11: 333.09677 | AV11: 335.15017 | AW11: 337.21879 | AX11: 339.30275 | AY11: 341.40218 | AZ11: 343.51717 | BA11: 345.64785 | BB11: 347.79434 | BC11: 349.95674 | BD11: 352.13519 | BE11: 354.32979 | BF11: 356.54067 | BG11: 358.76794 | BH11: 361.01174 | BI11: 363.27218 | BJ11: 365.54939 | BK11: 367.84348 | BL11: 370.15459 | BM11: 372.48285 | BN11: 374.82837 | BO11: 377.19129 | BP11: 379.57173 | BQ11: 381.96983 | BR11: 384.38572 | BS11: 386.81953 | BT11: 389.27138 | BU11: 391.74143 | BV11: 394.22979 | BW11: 396.73661 | BX11: 399.26203 | BY11: 401.80617 | BZ11: 404.36919 | CA11: 406.95121 | CB11: 409.55239 | CC11: 412.17286 | CD11: 414.81276 | CE11: 417.47225 | CF11: 420.15146 | CG11: 422.85054 | CH11: 425.56964 | CI11: 428.30891 | CJ11: 431.0685 | CK11: 433.84856 | CL11: 436.64923 | CM11: 439.47068 | CN11: 442.31306 | CO11: 445.17651 | CP11: 448.06121 | CQ11: 450.9673 | CR11: 453.89495 | CS11: 456.84431 | CT11: 459.81555 | CU11: 462.80882 | CV11: 465.8243 | CW11: 468.86214 | CX11: 471.92251 | CY11: 475.00559 | CZ11: 478.11153 | DA11: 481.2405 | DB11: 484.39269
A13: EBITDA | B13: INR Lakhs | C13: 0 | D13: 0 | E13: 0 | F13: 0 | G13: 1001.7842 | H13: 998.67329 | I13: 995.55301 | J13: 992.42329 | K13: 989.28405 | L13: 986.13519 | M13: 982.97664 | N13: 979.8083 | O13: 976.63008 | P13: 973.44189 | Q13: 970.24364 | R13: 967.03523 | S13: 963.81659 | T13: 960.58761 | U13: 957.34819 | V13: 954.09825 | W13: 950.83769 | X13: 947.56642 | Y13: 944.28433 | Z13: 940.99134 | AA13: 937.68734 | AB13: 934.37223 | AC13: 931.04592 | AD13: 927.7083 | AE13: 924.35928 | AF13: 920.99876 | AG13: 917.62662 | AH13: 914.24278 | AI13: 910.84712 | AJ13: 907.43954 | AK13: 904.01994 | AL13: 900.58821 | AM13: 897.14424 | AN13: 893.68793 | AO13: 890.21917 | AP13: 886.73785 | AQ13: 883.24386 | AR13: 879.73709 | AS13: 876.21743 | AT13: 872.68476 | AU13: 869.13898 | AV13: 865.57996 | AW13: 862.00761 | AX13: 858.42179 | AY13: 854.8224 | AZ13: 851.20931 | BA13: 847.58241 | BB13: 843.94158 | BC13: 840.28671 | BD13: 836.61766 | BE13: 832.93432 | BF13: 829.23657 | BG13: 825.52429 | BH13: 821.79734 | BI13: 818.05561 | BJ13: 814.29897 | BK13: 810.52729 | BL13: 806.74044 | BM13: 802.93831 | BN13: 799.12074 | BO13: 795.28763 | BP13: 791.43883 | BQ13: 787.57421 | BR13: 783.69365 | BS13: 779.797 | BT13: 775.88413 | BU13: 771.9549 | BV13: 768.00918 | BW13: 764.04683 | BX13: 760.06771 | BY13: 756.07167 | BZ13: 752.05859 | CA13: 748.02831 | CB13: 743.9807 | CC13: 739.9156 | CD13: 735.83288 | CE13: 731.73238 | CF13: 727.61396 | CG13: 723.47747 | CH13: 719.32276 | CI13: 715.14969 | CJ13: 710.95809 | CK13: 706.74782 | CL13: 702.51871 | CM13: 698.27063 | CN13: 694.0034 | CO13: 689.71688 | CP13: 685.4109 | CQ13: 681.0853 | CR13: 676.73993 | CS13: 672.37461 | CT13: 667.9892 | CU13: 663.58352 | CV13: 659.1574 | CW13: 654.71069 | CX13: 650.24321 | CY13: 645.75479 | CZ13: 641.24527 | DA13: 636.71446 | DB13: 632.16221
A15: BELOW-THE-LINE (P&L)
A16: Depreciation | B16: INR Lakhs | C16: 0 | D16: 0 | E16: 0 | F16: 0 | G16: 534.375 | H16: 534.375 | I16: 534.375 | J16: 534.375 | K16: 534.375 | L16: 534.375 | M16: 534.375 | N16: 534.375 | O16: 534.375 | P16: 534.375 | Q16: 534.375 | R16: 534.375 | S16: 534.375 | T16: 534.375 | U16: 534.375 | V16: 534.375 | W16: 534.375 | X16: 534.375 | Y16: 534.375 | Z16: 534.375 | AA16: 534.375 | AB16: 534.375 | AC16: 534.375 | AD16: 534.375 | AE16: 534.375 | AF16: 534.375 | AG16: 534.375 | AH16: 534.375 | AI16: 534.375 | AJ16: 534.375 | AK16: 534.375 | AL16: 534.375 | AM16: 534.375 | AN16: 534.375 | AO16: 534.375 | AP16: 534.375 | AQ16: 534.375 | AR16: 534.375 | AS16: 534.375 | AT16: 534.375 | AU16: 534.375 | AV16: 534.375 | AW16: 534.375 | AX16: 534.375 | AY16: 534.375 | AZ16: 534.375 | BA16: 534.375 | BB16: 534.375 | BC16: 534.375 | BD16: 534.375 | BE16: 534.375 | BF16: 534.375 | BG16: 534.375 | BH16: 534.375 | BI16: 534.375 | BJ16: 534.375 | BK16: 534.375 | BL16: 534.375 | BM16: 534.375 | BN16: 534.375 | BO16: 534.375 | BP16: 534.375 | BQ16: 534.375 | BR16: 534.375 | BS16: 534.375 | BT16: 534.375 | BU16: 534.375 | BV16: 534.375 | BW16: 534.375 | BX16: 534.375 | BY16: 534.375 | BZ16: 534.375 | CA16: 534.375 | CB16: 534.375 | CC16: 534.375 | CD16: 534.375 | CE16: 534.375 | CF16: 534.375 | CG16: 534.375 | CH16: 534.375 | CI16: 534.375 | CJ16: 534.375 | CK16: 534.375 | CL16: 534.375 | CM16: 534.375 | CN16: 534.375 | CO16: 534.375 | CP16: 534.375 | CQ16: 534.375 | CR16: 534.375 | CS16: 534.375 | CT16: 534.375 | CU16: 534.375 | CV16: 534.375 | CW16: 534.375 | CX16: 534.375 | CY16: 534.375 | CZ16: 534.375 | DA16: 534.375 | DB16: 534.375
A17: EBIT | B17: INR Lakhs | C17: 0 | D17: 0 | E17: 0 | F17: 0 | G17: 467.40922 | H17: 464.29829 | I17: 461.17801 | J17: 458.04829 | K17: 454.90905 | L17: 451.76019 | M17: 448.60164 | N17: 445.4333 | O17: 442.25508 | P17: 439.06689 | Q17: 435.86864 | R17: 432.66023 | S17: 429.44159 | T17: 426.21261 | U17: 422.97319 | V17: 419.72325 | W17: 416.46269 | X17: 413.19142 | Y17: 409.90933 | Z17: 406.61634 | AA17: 403.31234 | AB17: 399.99723 | AC17: 396.67092 | AD17: 393.3333 | AE17: 389.98428 | AF17: 386.62376 | AG17: 383.25162 | AH17: 379.86778 | AI17: 376.47212 | AJ17: 373.06454 | AK17: 369.64494 | AL17: 366.21321 | AM17: 362.76924 | AN17: 359.31293 | AO17: 355.84417 | AP17: 352.36285 | AQ17: 348.86886 | AR17: 345.36209 | AS17: 341.84243 | AT17: 338.30976 | AU17: 334.76398 | AV17: 331.20496 | AW17: 327.63261 | AX17: 324.04679 | AY17: 320.4474 | AZ17: 316.83431 | BA17: 313.20741 | BB17: 309.56658 | BC17: 305.91171 | BD17: 302.24266 | BE17: 298.55932 | BF17: 294.86157 | BG17: 291.14929 | BH17: 287.42234 | BI17: 283.68061 | BJ17: 279.92397 | BK17: 276.15229 | BL17: 272.36544 | BM17: 268.56331 | BN17: 264.74574 | BO17: 260.91263 | BP17: 257.06383 | BQ17: 253.19921 | BR17: 249.31865 | BS17: 245.422 | BT17: 241.50913 | BU17: 237.5799 | BV17: 233.63418 | BW17: 229.67183 | BX17: 225.69271 | BY17: 221.69667 | BZ17: 217.68359 | CA17: 213.65331 | CB17: 209.6057 | CC17: 205.5406 | CD17: 201.45788 | CE17: 197.35738 | CF17: 193.23896 | CG17: 189.10247 | CH17: 184.94776 | CI17: 180.77469 | CJ17: 176.58309 | CK17: 172.37282 | CL17: 168.14371 | CM17: 163.89563 | CN17: 159.6284 | CO17: 155.34188 | CP17: 151.0359 | CQ17: 146.7103 | CR17: 142.36493 | CS17: 137.99961 | CT17: 133.6142 | CU17: 129.20852 | CV17: 124.7824 | CW17: 120.33569 | CX17: 115.86821 | CY17: 111.37979 | CZ17: 106.87027 | DA17: 102.33946 | DB17: 97.787206
A18: Interest Expense | B18: INR Lakhs | C18: 0 | D18: 0 | E18: 0 | F18: 0 | G18: 741.23626 | H18: 730.94131 | I18: 720.64636 | J18: 710.35141 | K18: 700.05646 | L18: 689.76152 | M18: 679.46657 | N18: 669.17162 | O18: 658.87667 | P18: 648.58172 | Q18: 638.28678 | R18: 627.99183 | S18: 617.69688 | T18: 607.40193 | U18: 597.10698 | V18: 586.81204 | W18: 576.51709 | X18: 566.22214 | Y18: 555.92719 | Z18: 545.63224 | AA18: 535.3373 | AB18: 525.04235 | AC18: 514.7474 | AD18: 504.45245 | AE18: 494.1575 | AF18: 483.86256 | AG18: 473.56761 | AH18: 463.27266 | AI18: 452.97771 | AJ18: 442.68276 | AK18: 432.38782 | AL18: 422.09287 | AM18: 411.79792 | AN18: 401.50297 | AO18: 391.20802 | AP18: 380.91308 | AQ18: 370.61813 | AR18: 360.32318 | AS18: 350.02823 | AT18: 339.73328 | AU18: 329.43834 | AV18: 319.14339 | AW18: 308.84844 | AX18: 298.55349 | AY18: 288.25854 | AZ18: 277.9636 | BA18: 267.66865 | BB18: 257.3737 | BC18: 247.07875 | BD18: 236.7838 | BE18: 226.48886 | BF18: 216.19391 | BG18: 205.89896 | BH18: 195.60401 | BI18: 185.30906 | BJ18: 175.01412 | BK18: 164.71917 | BL18: 154.42422 | BM18: 144.12927 | BN18: 133.83432 | BO18: 123.53938 | BP18: 113.24443 | BQ18: 102.94948 | BR18: 92.654532 | BS18: 82.359584 | BT18: 72.064636 | BU18: 61.769688 | BV18: 51.47474 | BW18: 41.179792 | BX18: 30.884844 | BY18: 20.589896 | BZ18: 10.294948 | CA18: 0 | CB18: 0 | CC18: 0 | CD18: 0 | CE18: 0 | CF18: 0 | CG18: 0 | CH18: 0 | CI18: 0 | CJ18: 0 | CK18: 0 | CL18: 0 | CM18: 0 | CN18: 0 | CO18: 0 | CP18: 0 | CQ18: 0 | CR18: 0 | CS18: 0 | CT18: 0 | CU18: 0 | CV18: 0 | CW18: 0 | CX18: 0 | CY18: 0 | CZ18: 0 | DA18: 0 | DB18: 0
A19: PBT | B19: INR Lakhs | C19: 0 | D19: 0 | E19: 0 | F19: 0 | G19: -273.82704 | H19: -266.64302 | I19: -259.46835 | J19: -252.30312 | K19: -245.14742 | L19: -238.00132 | M19: -230.86493 | N19: -223.73832 | O19: -216.62159 | P19: -209.51484 | Q19: -202.41814 | R19: -195.33159 | S19: -188.25529 | T19: -181.18933 | U19: -174.13379 | V19: -167.08878 | W19: -160.05439 | X19: -153.03072 | Y19: -146.01786 | Z19: -139.01591 | AA19: -132.02496 | AB19: -125.04512 | AC19: -118.07648 | AD19: -111.11915 | AE19: -104.17322 | AF19: -97.238798 | AG19: -90.315984 | AH19: -83.40488 | AI19: -76.505592 | AJ19: -69.618221 | AK19: -62.742874 | AL19: -55.879657 | AM19: -49.028676 | AN19: -42.190038 | AO19: -35.363851 | AP19: -28.550224 | AQ19: -21.749267 | AR19: -14.961091 | AS19: -8.1858056 | AT19: -1.4235241 | AU19: 5.3256409 | AV19: 12.061576 | AW19: 18.784166 | AX19: 25.493297 | AY19: 32.188851 | AZ19: 38.870712 | BA19: 45.538763 | BB19: 52.192883 | BC19: 58.832955 | BD19: 65.458857 | BE19: 72.070468 | BF19: 78.667666 | BG19: 85.250327 | BH19: 91.818329 | BI19: 98.371545 | BJ19: 104.90985 | BK19: 111.43312 | BL19: 117.94122 | BM19: 124.43403 | BN19: 130.91142 | BO19: 137.37325 | BP19: 143.8194 | BQ19: 150.24973 | BR19: 156.66412 | BS19: 163.06241 | BT19: 169.44449 | BU19: 175.81021 | BV19: 182.15944 | BW19: 188.49204 | BX19: 194.80786 | BY19: 201.10678 | BZ19: 207.38864 | CA19: 213.65331 | CB19: 209.6057 | CC19: 205.5406 | CD19: 201.45788 | CE19: 197.35738 | CF19: 193.23896 | CG19: 189.10247 | CH19: 184.94776 | CI19: 180.77469 | CJ19: 176.58309 | CK19: 172.37282 | CL19: 168.14371 | CM19: 163.89563 | CN19: 159.6284 | CO19: 155.34188 | CP19: 151.0359 | CQ19: 146.7103 | CR19: 142.36493 | CS19: 137.99961 | CT19: 133.6142 | CU19: 129.20852 | CV19: 124.7824 | CW19: 120.33569 | CX19: 115.86821 | CY19: 111.37979 | CZ19: 106.87027 | DA19: 102.33946 | DB19: 97.787206
A20: Tax | B20: INR Lakhs | C20: 0 | D20: 0 | E20: 0 | F20: 0 | G20: 0 | H20: 0 | I20: 0 | J20: 0 | K20: 0 | L20: 0 | M20: 0 | N20: 0 | O20: 0 | P20: 0 | Q20: 0 | R20: 0 | S20: 0 | T20: 0 | U20: 0 | V20: 0 | W20: 0 | X20: 0 | Y20: 0 | Z20: 0 | AA20: 0 | AB20: 0 | AC20: 0 | AD20: 0 | AE20: 0 | AF20: 0 | AG20: 0 | AH20: 0 | AI20: 0 | AJ20: 0 | AK20: 0 | AL20: 0 | AM20: 0 | AN20: 0 | AO20: 0 | AP20: 0 | AQ20: 0 | AR20: 0 | AS20: 0 | AT20: 0 | AU20: 1.3314102 | AV20: 3.015394 | AW20: 4.6960415 | AX20: 6.3733241 | AY20: 8.0472127 | AZ20: 9.717678 | BA20: 11.384691 | BB20: 13.048221 | BC20: 14.708239 | BD20: 16.364714 | BE20: 18.017617 | BF20: 19.666916 | BG20: 21.312582 | BH20: 22.954582 | BI20: 24.592886 | BJ20: 26.227463 | BK20: 27.85828 | BL20: 29.485306 | BM20: 31.108508 | BN20: 32.727855 | BO20: 34.343313 | BP20: 35.954851 | BQ20: 37.562433 | BR20: 39.166029 | BS20: 40.765603 | BT20: 42.361122 | BU20: 43.952553 | BV20: 45.53986 | BW20: 47.123009 | BX20: 48.701966 | BY20: 50.276695 | BZ20: 51.847161 | CA20: 53.413328 | CB20: 52.401424 | CC20: 51.38515 | CD20: 50.364469 | CE20: 49.339345 | CF20: 48.30974 | CG20: 47.275618 | CH20: 46.236941 | CI20: 45.193672 | CJ20: 44.145772 | CK20: 43.093204 | CL20: 42.035928 | CM20: 40.973907 | CN20: 39.9071 | CO20: 38.835469 | CP20: 37.758974 | CQ20: 36.677575 | CR20: 35.591232 | CS20: 34.499904 | CT20: 33.40355 | CU20: 32.30213 | CV20: 31.195601 | CW20: 30.083923 | CX20: 28.967052 | CY20: 27.844948 | CZ20: 26.717567 | DA20: 25.584866 | DB20: 24.446801
A21: PAT (PBT − Tax) | B21: INR Lakhs | C21: 0 | D21: 0 | E21: 0 | F21: 0 | G21: -273.82704 | H21: -266.64302 | I21: -259.46835 | J21: -252.30312 | K21: -245.14742 | L21: -238.00132 | M21: -230.86493 | N21: -223.73832 | O21: -216.62159 | P21: -209.51484 | Q21: -202.41814 | R21: -195.33159 | S21: -188.25529 | T21: -181.18933 | U21: -174.13379 | V21: -167.08878 | W21: -160.05439 | X21: -153.03072 | Y21: -146.01786 | Z21: -139.01591 | AA21: -132.02496 | AB21: -125.04512 | AC21: -118.07648 | AD21: -111.11915 | AE21: -104.17322 | AF21: -97.238798 | AG21: -90.315984 | AH21: -83.40488 | AI21: -76.505592 | AJ21: -69.618221 | AK21: -62.742874 | AL21: -55.879657 | AM21: -49.028676 | AN21: -42.190038 | AO21: -35.363851 | AP21: -28.550224 | AQ21: -21.749267 | AR21: -14.961091 | AS21: -8.1858056 | AT21: -1.4235241 | AU21: 3.9942307 | AV21: 9.0461819 | AW21: 14.088125 | AX21: 19.119972 | AY21: 24.141638 | AZ21: 29.153034 | BA21: 34.154072 | BB21: 39.144662 | BC21: 44.124716 | BD21: 49.094142 | BE21: 54.052851 | BF21: 59.000749 | BG21: 63.937745 | BH21: 68.863747 | BI21: 73.778659 | BJ21: 78.682388 | BK21: 83.57484 | BL21: 88.455917 | BM21: 93.325525 | BN21: 98.183565 | BO21: 103.02994 | BP21: 107.86455 | BQ21: 112.6873 | BR21: 117.49809 | BS21: 122.29681 | BT21: 127.08337 | BU21: 131.85766 | BV21: 136.61958 | BW21: 141.36903 | BX21: 146.1059 | BY21: 150.83008 | BZ21: 155.54148 | CA21: 160.23998 | CB21: 157.20427 | CC21: 154.15545 | CD21: 151.09341 | CE21: 148.01803 | CF21: 144.92922 | CG21: 141.82685 | CH21: 138.71082 | CI21: 135.58102 | CJ21: 132.43732 | CK21: 129.27961 | CL21: 126.10779 | CM21: 122.92172 | CN21: 119.7213 | CO21: 116.50641 | CP21: 113.27692 | CQ21: 110.03273 | CR21: 106.7737 | CS21: 103.49971 | CT21: 100.21065 | CU21: 96.906389 | CV21: 93.586803 | CW21: 90.251768 | CX21: 86.901157 | CY21: 83.534844 | CZ21: 80.1527 | DA21: 76.754597 | DB21: 73.340404
A23: EBITDA MARGIN
A24: EBITDA Margin % | B24: % | G24: 0.79252935 | H24: 0.79105892 | I24: 0.78957614 | J24: 0.78808091 | K24: 0.78657311 | L24: 0.78505264 | M24: 0.78351938 | N24: 0.78197324 | O24: 0.78041409 | P24: 0.77884183 | Q24: 0.77725633 | R24: 0.7756575 | S24: 0.7740452 | T24: 0.77241933 | U24: 0.77077977 | V24: 0.7691264 | W24: 0.76745909 | X24: 0.76577774 | Y24: 0.76408221 | Z24: 0.76237239 | AA24: 0.76064816 | AB24: 0.75890937 | AC24: 0.75715593 | AD24: 0.75538768 | AE24: 0.75360452 | AF24: 0.7518063 | AG24: 0.7499929 | AH24: 0.74816418 | AI24: 0.74632002 | AJ24: 0.74446028 | AK24: 0.74258483 | AL24: 0.74069353 | AM24: 0.73878624 | AN24: 0.73686283 | AO24: 0.73492315 | AP24: 0.73296706 | AQ24: 0.73099443 | AR24: 0.72900511 | AS24: 0.72699896 | AT24: 0.72497582 | AU24: 0.72293556 | AV24: 0.72087802 | AW24: 0.71880306 | AX24: 0.71671053 | AY24: 0.71460026 | AZ24: 0.71247212 | BA24: 0.71032594 | BB24: 0.70816157 | BC24: 0.70597885 | BD24: 0.70377763 | BE24: 0.70155774 | BF24: 0.69931902 | BG24: 0.6970613 | BH24: 0.69478444 | BI24: 0.69248825 | BJ24: 0.69017257 | BK24: 0.68783723 | BL24: 0.68548207 | BM24: 0.6831069 | BN24: 0.68071157 | BO24: 0.67829589 | BP24: 0.67585969 | BQ24: 0.67340278 | BR24: 0.670925 | BS24: 0.66842615 | BT24: 0.66590607 | BU24: 0.66336456 | BV24: 0.66080143 | BW24: 0.65821651 | BX24: 0.6556096 | BY24: 0.65298052 | BZ24: 0.65032906 | CA24: 0.64765504 | CB24: 0.64495827 | CC24: 0.64223853 | CD24: 0.63949565 | CE24: 0.63672941 | CF24: 0.63393961 | CG24: 0.63112605 | CH24: 0.62828853 | CI24: 0.62542683 | CJ24: 0.62254075 | CK24: 0.61963007 | CL24: 0.61669459 | CM24: 0.61373409 | CN24: 0.61074835 | CO24: 0.60773715 | CP24: 0.60470028 | CQ24: 0.6016375 | CR24: 0.5985486 | CS24: 0.59543336 | CT24: 0.59229153 | CU24: 0.5891229 | CV24: 0.58592722 | CW24: 0.58270427 | CX24: 0.57945382 | CY24: 0.57617561 | CZ24: 0.57286941 | DA24: 0.56953498 | DB24: 0.56617208
A26: PPA Revenue | B26: =Assumptions!B28 -> 2.65 | G26: =G4*$B$26/10^5 -> 1264.0342 | H26: =H4*$B$26/10^5 -> 1262.4512 | I26: =I4*$B$26/10^5 -> 1260.8702 | J26: =J4*$B$26/10^5 -> 1259.2911 | K26: =K4*$B$26/10^5 -> 1257.714 | L26: =L4*$B$26/10^5 -> 1256.1389 | M26: =M4*$B$26/10^5 -> 1254.5658 | N26: =N4*$B$26/10^5 -> 1252.9947 | ... DB26: =DB4*$B$26/10^5 -> 1116.5549
A27: Total Opex | G27: =G11 -> 262.25 | H27: =H11 -> 263.77792 | I27: =I11 -> 265.31717 | J27: =J11 -> 266.86783 | K27: =K11 -> 268.43 | L27: =L11 -> 270.00375 | M27: =M11 -> 271.58918 | N27: =N11 -> 273.18637 | ... DB27: =DB11 -> 484.39269
A29: EBITDA | G29: =G26-G27 -> 1001.7842 | H29: =H26-H27 -> 998.67329 | I29: =I26-I27 -> 995.55301 | J29: =J26-J27 -> 992.42329 | K29: =K26-K27 -> 989.28405 | L29: =L26-L27 -> 986.13519 | M29: =M26-M27 -> 982.97664 | N29: =N26-N27 -> 979.8083 | ... DB29: =DB26-DB27 -> 632.16221
B30: =SUM('Cash Flow'!C27:F27)*95% -> 42750
A31: Depreciation | B31: =Assumptions!B14 -> 0.05 | G31: =$B$30*$B$31/4 -> 534.375 | H31: =$B$30*$B$31/4 -> 534.375 | I31: =$B$30*$B$31/4 -> 534.375 | J31: =$B$30*$B$31/4 -> 534.375 | K31: =$B$30*$B$31/4 -> 534.375 | L31: =$B$30*$B$31/4 -> 534.375 | M31: =$B$30*$B$31/4 -> 534.375 | N31: =$B$30*$B$31/4 -> 534.375 | ... DB31: =$B$30*$B$31/4 -> 534.375
A33: EBIT | G33: =G29-G31 -> 467.40922 | H33: =H29-H31 -> 464.29829 | I33: =I29-I31 -> 461.17801 | J33: =J29-J31 -> 458.04829 | K33: =K29-K31 -> 454.90905 | L33: =L29-L31 -> 451.76019 | M33: =M29-M31 -> 448.60164 | N33: =N29-N31 -> 445.4333 | ... DB33: =DB29-DB31 -> 97.787206
A35: Interest | G35: ='Debt Schedule'!G14 -> 741.23626 | H35: ='Debt Schedule'!H14 -> 730.94131 | I35: ='Debt Schedule'!I14 -> 720.64636 | J35: ='Debt Schedule'!J14 -> 710.35141 | K35: ='Debt Schedule'!K14 -> 700.05646 | L35: ='Debt Schedule'!L14 -> 689.76152 | M35: ='Debt Schedule'!M14 -> 679.46657 | N35: ='Debt Schedule'!N14 -> 669.17162 | ... DB35: ='Debt Schedule'!DB14 -> 0
A37: PBT | G37: =G33-G35 -> -273.82704 | H37: =H33-H35 -> -266.64302 | I37: =I33-I35 -> -259.46835 | J37: =J33-J35 -> -252.30312 | K37: =K33-K35 -> -245.14742 | L37: =L33-L35 -> -238.00132 | M37: =M33-M35 -> -230.86493 | N37: =N33-N35 -> -223.73832 | ... DB37: =DB33-DB35 -> 97.787206
A39: Tax | B39: =Assumptions!B30 -> 0.25 | G39: =(G37>0)*G37*$B$39 -> 0 | H39: =(H37>0)*H37*$B$39 -> 0 | I39: =(I37>0)*I37*$B$39 -> 0 | J39: =(J37>0)*J37*$B$39 -> 0 | K39: =(K37>0)*K37*$B$39 -> 0 | L39: =(L37>0)*L37*$B$39 -> 0 | M39: =(M37>0)*M37*$B$39 -> 0 | N39: =(N37>0)*N37*$B$39 -> 0 | ... DB39: =(DB37>0)*DB37*$B$39 -> 24.446801
A41: PAT | G41: =G37-G39 -> -273.82704 | H41: =H37-H39 -> -266.64302 | I41: =I37-I39 -> -259.46835 | J41: =J37-J39 -> -252.30312 | K41: =K37-K39 -> -245.14742 | L41: =L37-L39 -> -238.00132 | M41: =M37-M39 -> -230.86493 | N41: =N37-N39 -> -223.73832 | ... DB41: =DB37-DB39 -> 73.340404
A43: Cashflow
A45: PAT | G45: =G41 -> -273.82704 | H45: =H41 -> -266.64302 | I45: =I41 -> -259.46835 | J45: =J41 -> -252.30312 | K45: =K41 -> -245.14742 | L45: =L41 -> -238.00132 | M45: =M41 -> -230.86493 | N45: =N41 -> -223.73832 | ... DB45: =DB41 -> 73.340404
A46: Add: Dep | G46: =G31 -> 534.375 | H46: =H31 -> 534.375 | I46: =I31 -> 534.375 | J46: =J31 -> 534.375 | K46: =K31 -> 534.375 | L46: =L31 -> 534.375 | M46: =M31 -> 534.375 | N46: =N31 -> 534.375 | ... DB46: =DB31 -> 534.375
A47: Less: Repayment | G47: ='Debt Schedule'!G15 -> 437.5 | H47: ='Debt Schedule'!H15 -> 437.5 | I47: ='Debt Schedule'!I15 -> 437.5 | J47: ='Debt Schedule'!J15 -> 437.5 | K47: ='Debt Schedule'!K15 -> 437.5 | L47: ='Debt Schedule'!L15 -> 437.5 | M47: ='Debt Schedule'!M15 -> 437.5 | N47: ='Debt Schedule'!N15 -> 437.5 | ... DB47: ='Debt Schedule'!DB15 -> 0
A48: FCFE | G48: =G45+G46-G47 -> -176.95204 | H48: =H45+H46-H47 -> -169.76802 | I48: =I45+I46-I47 -> -162.59335 | J48: =J45+J46-J47 -> -155.42812 | K48: =K45+K46-K47 -> -148.27242 | L48: =L45+L46-L47 -> -141.12632 | M48: =M45+M46-M47 -> -133.98993 | N48: =N45+N46-N47 -> -126.86332 | ... DB48: =DB45+DB46-DB47 -> 607.7154

Sheet Cash Flow
A1: CASH FLOW
A2: Line Item | B2: Unit | C2: Q1 CON | D2: Q2 CON | E2: Q3 CON | F2: Q4 CON | G2: Q1 OPS | H2: Q2 OPS | I2: Q3 OPS | J2: Q4 OPS | K2: Q5 OPS | L2: Q6 OPS | M2: Q7 OPS | N2: Q8 OPS | O2: Q9 OPS | P2: Q10 OPS | Q2: Q11 OPS | R2: Q12 OPS | S2: Q13 OPS | T2: Q14 OPS | U2: Q15 OPS | V2: Q16 OPS | W2: Q17 OPS | X2: Q18 OPS | Y2: Q19 OPS | Z2: Q20 OPS | AA2: Q21 OPS | AB2: Q22 OPS | AC2: Q23 OPS | AD2: Q24 OPS | AE2: Q25 OPS | AF2: Q26 OPS | AG2: Q27 OPS | AH2: Q28 OPS | AI2: Q29 OPS | AJ2: Q30 OPS | AK2: Q31 OPS | AL2: Q32 OPS | AM2: Q33 OPS | AN2: Q34 OPS | AO2: Q35 OPS | AP2: Q36 OPS | AQ2: Q37 OPS | AR2: Q38 OPS | AS2: Q39 OPS | AT2: Q40 OPS | AU2: Q41 OPS | AV2: Q42 OPS | AW2: Q43 OPS | AX2: Q44 OPS | AY2: Q45 OPS | AZ2: Q46 OPS | BA2: Q47 OPS | BB2: Q48 OPS | BC2: Q49 OPS | BD2: Q50 OPS | BE2: Q51 OPS | BF2: Q52 OPS | BG2: Q53 OPS | BH2: Q54 OPS | BI2: Q55 OPS | BJ2: Q56 OPS | BK2: Q57 OPS | BL2: Q58 OPS | BM2: Q59 OPS | BN2: Q60 OPS | BO2: Q61 OPS | BP2: Q62 OPS | BQ2: Q63 OPS | BR2: Q64 OPS | BS2: Q65 OPS | BT2: Q66 OPS | BU2: Q67 OPS | BV2: Q68 OPS | BW2: Q69 OPS | BX2: Q70 OPS | BY2: Q71 OPS | BZ2: Q72 OPS | CA2: Q73 OPS | CB2: Q74 OPS | CC2: Q75 OPS | CD2: Q76 OPS | CE2: Q77 OPS | CF2: Q78 OPS | CG2: Q79 OPS | CH2: Q80 OPS | CI2: Q81 OPS | CJ2: Q82 OPS | CK2: Q83 OPS | CL2: Q84 OPS | CM2: Q85 OPS | CN2: Q86 OPS | CO2: Q87 OPS | CP2: Q88 OPS | CQ2: Q89 OPS | CR2: Q90 OPS | CS2: Q91 OPS | CT2: Q92 OPS | CU2: Q93 OPS | CV2: Q94 OPS | CW2: Q95 OPS | CX2: Q96 OPS | CY2: Q97 OPS | CZ2: Q98 OPS | DA2: Q99 OPS | DB2: Q100 OPS
A3: OPERATING CASH FLOW
A4: EBITDA | B4: INR Lakhs | C4: 0 | D4: 0 | E4: 0 | F4: 0 | G4: 1001.7842 | H4: 998.67329 | I4: 995.55301 | J4: 992.42329 | K4: 989.28405 | L4: 986.13519 | M4: 982.97664 | N4: 979.8083 | O4: 976.63008 | P4: 973.44189 | Q4: 970.24364 | R4: 967.03523 | S4: 963.81659 | T4: 960.58761 | U4: 957.34819 | V4: 954.09825 | W4: 950.83769 | X4: 947.56642 | Y4: 944.28433 | Z4: 940.99134 | AA4: 937.68734 | AB4: 934.37223 | AC4: 931.04592 | AD4: 927.7083 | AE4: 924.35928 | AF4: 920.99876 | AG4: 917.62662 | AH4: 914.24278 | AI4: 910.84712 | AJ4: 907.43954 | AK4: 904.01994 | AL4: 900.58821 | AM4: 897.14424 | AN4: 893.68793 | AO4: 890.21917 | AP4: 886.73785 | AQ4: 883.24386 | AR4: 879.73709 | AS4: 876.21743 | AT4: 872.68476 | AU4: 869.13898 | AV4: 865.57996 | AW4: 862.00761 | AX4: 858.42179 | AY4: 854.8224 | AZ4: 851.20931 | BA4: 847.58241 | BB4: 843.94158 | BC4: 840.28671 | BD4: 836.61766 | BE4: 832.93432 | BF4: 829.23657 | BG4: 825.52429 | BH4: 821.79734 | BI4: 818.05561 | BJ4: 814.29897 | BK4: 810.52729 | BL4: 806.74044 | BM4: 802.93831 | BN4: 799.12074 | BO4: 795.28763 | BP4: 791.43883 | BQ4: 787.57421 | BR4: 783.69365 | BS4: 779.797 | BT4: 775.88413 | BU4: 771.9549 | BV4: 768.00918 | BW4: 764.04683 | BX4: 760.06771 | BY4: 756.07167 | BZ4: 752.05859 | CA4: 748.02831 | CB4: 743.9807 | CC4: 739.9156 | CD4: 735.83288 | CE4: 731.73238 | CF4: 727.61396 | CG4: 723.47747 | CH4: 719.32276 | CI4: 715.14969 | CJ4: 710.95809 | CK4: 706.74782 | CL4: 702.51871 | CM4: 698.27063 | CN4: 694.0034 | CO4: 689.71688 | CP4: 685.4109 | CQ4: 681.0853 | CR4: 676.73993 | CS4: 672.37461 | CT4: 667.9892 | CU4: 663.58352 | CV4: 659.1574 | CW4: 654.71069 | CX4: 650.24321 | CY4: 645.75479 | CZ4: 641.24527 | DA4: 636.71446 | DB4: 632.16221
A5: Tax Paid | B5: INR Lakhs | C5: 0 | D5: 0 | E5: 0 | F5: 0 | G5: 0 | H5: 0 | I5: 0 | J5: 0 | K5: 0 | L5: 0 | M5: 0 | N5: 0 | O5: 0 | P5: 0 | Q5: 0 | R5: 0 | S5: 0 | T5: 0 | U5: 0 | V5: 0 | W5: 0 | X5: 0 | Y5: 0 | Z5: 0 | AA5: 0 | AB5: 0 | AC5: 0 | AD5: 0 | AE5: 0 | AF5: 0 | AG5: 0 | AH5: 0 | AI5: 0 | AJ5: 0 | AK5: 0 | AL5: 0 | AM5: 0 | AN5: 0 | AO5: 0 | AP5: 0 | AQ5: 0 | AR5: 0 | AS5: 0 | AT5: 0 | AU5: -1.3314102 | AV5: -3.015394 | AW5: -4.6960415 | AX5: -6.3733241 | AY5: -8.0472127 | AZ5: -9.717678 | BA5: -11.384691 | BB5: -13.048221 | BC5: -14.708239 | BD5: -16.364714 | BE5: -18.017617 | BF5: -19.666916 | BG5: -21.312582 | BH5: -22.954582 | BI5: -24.592886 | BJ5: -26.227463 | BK5: -27.85828 | BL5: -29.485306 | BM5: -31.108508 | BN5: -32.727855 | BO5: -34.343313 | BP5: -35.954851 | BQ5: -37.562433 | BR5: -39.166029 | BS5: -40.765603 | BT5: -42.361122 | BU5: -43.952553 | BV5: -45.53986 | BW5: -47.123009 | BX5: -48.701966 | BY5: -50.276695 | BZ5: -51.847161 | CA5: -53.413328 | CB5: -52.401424 | CC5: -51.38515 | CD5: -50.364469 | CE5: -49.339345 | CF5: -48.30974 | CG5: -47.275618 | CH5: -46.236941 | CI5: -45.193672 | CJ5: -44.145772 | CK5: -43.093204 | CL5: -42.035928 | CM5: -40.973907 | CN5: -39.9071 | CO5: -38.835469 | CP5: -37.758974 | CQ5: -36.677575 | CR5: -35.591232 | CS5: -34.499904 | CT5: -33.40355 | CU5: -32.30213 | CV5: -31.195601 | CW5: -30.083923 | CX5: -28.967052 | CY5: -27.844948 | CZ5: -26.717567 | DA5: -25.584866 | DB5: -24.446801
A6: Maintenance Capex | B6: INR Lakhs | C6: 0 | D6: 0 | E6: 0 | F6: 0 | G6: 0 | H6: 0 | I6: 0 | J6: 0 | K6: 0 | L6: 0 | M6: 0 | N6: 0 | O6: 0 | P6: 0 | Q6: 0 | R6: 0 | S6: 0 | T6: 0 | U6: 0 | V6: 0 | W6: 0 | X6: 0 | Y6: 0 | Z6: 0 | AA6: 0 | AB6: 0 | AC6: 0 | AD6: 0 | AE6: 0 | AF6: 0 | AG6: 0 | AH6: 0 | AI6: 0 | AJ6: 0 | AK6: 0 | AL6: 0 | AM6: 0 | AN6: 0 | AO6: 0 | AP6: 0 | AQ6: 0 | AR6: 0 | AS6: 0 | AT6: 0 | AU6: 0 | AV6: 0 | AW6: 0 | AX6: 0 | AY6: 0 | AZ6: 0 | BA6: 0 | BB6: 0 | BC6: 0 | BD6: 0 | BE6: 0 | BF6: 0 | BG6: 0 | BH6: 0 | BI6: 0 | BJ6: 0 | BK6: 0 | BL6: 0 | BM6: 0 | BN6: 0 | BO6: 0 | BP6: 0 | BQ6: 0 | BR6: 0 | BS6: 0 | BT6: 0 | BU6: 0 | BV6: 0 | BW6: 0 | BX6: 0 | BY6: 0 | BZ6: 0 | CA6: 0 | CB6: 0 | CC6: 0 | CD6: 0 | CE6: 0 | CF6: 0 | CG6: 0 | CH6: 0 | CI6: 0 | CJ6: 0 | CK6: 0 | CL6: 0 | CM6: 0 | CN6: 0 | CO6: 0 | CP6: 0 | CQ6: 0 | CR6: 0 | CS6: 0 | CT6: 0 | CU6: 0 | CV6: 0 | CW6: 0 | CX6: 0 | CY6: 0 | CZ6: 0 | DA6: 0 | DB6: 0
A7: CFADS (pre-debt-svc) | B7: INR Lakhs | C7: 0 | D7: 0 | E7: 0 | F7: 0 | G7: 1001.7842 | H7: 998.67329 | I7: 995.55301 | J7: 992.42329 | K7: 989.28405 | L7: 986.13519 | M7: 982.97664 | N7: 979.8083 | O7: 976.63008 | P7: 973.44189 | Q7: 970.24364 | R7: 967.03523 | S7: 963.81659 | T7: 960.58761 | U7: 957.34819 | V7: 954.09825 | W7: 950.83769 | X7: 947.56642 | Y7: 944.28433 | Z7: 940.99134 | AA7: 937.68734 | AB7: 934.37223 | AC7: 931.04592 | AD7: 927.7083 | AE7: 924.35928 | AF7: 920.99876 | AG7: 917.62662 | AH7: 914.24278 | AI7: 910.84712 | AJ7: 907.43954 | AK7: 904.01994 | AL7: 900.58821 | AM7: 897.14424 | AN7: 893.68793 | AO7: 890.21917 | AP7: 886.73785 | AQ7: 883.24386 | AR7: 879.73709 | AS7: 876.21743 | AT7: 872.68476 | AU7: 867.80757 | AV7: 862.56457 | AW7: 857.31156 | AX7: 852.04846 | AY7: 846.77518 | AZ7: 841.49163 | BA7: 836.19772 | BB7: 830.89336 | BC7: 825.57847 | BD7: 820.25295 | BE7: 814.91671 | BF7: 809.56966 | BG7: 804.21171 | BH7: 798.84276 | BI7: 793.46272 | BJ7: 788.0715 | BK7: 782.66901 | BL7: 777.25514 | BM7: 771.8298 | BN7: 766.39289 | BO7: 760.94432 | BP7: 755.48398 | BQ7: 750.01178 | BR7: 744.52762 | BS7: 739.03139 | BT7: 733.523 | BU7: 728.00235 | BV7: 722.46932 | BW7: 716.92382 | BX7: 711.36574 | BY7: 705.79498 | BZ7: 700.21143 | CA7: 694.61498 | CB7: 691.57927 | CC7: 688.53045 | CD7: 685.46841 | CE7: 682.39303 | CF7: 679.30422 | CG7: 676.20185 | CH7: 673.08582 | CI7: 669.95602 | CJ7: 666.81232 | CK7: 663.65461 | CL7: 660.48279 | CM7: 657.29672 | CN7: 654.0963 | CO7: 650.88141 | CP7: 647.65192 | CQ7: 644.40773 | CR7: 641.1487 | CS7: 637.87471 | CT7: 634.58565 | CU7: 631.28139 | CV7: 627.9618 | CW7: 624.62677 | CX7: 621.27616 | CY7: 617.90984 | CZ7: 614.5277 | DA7: 611.1296 | DB7: 607.7154
A9: DEBT SERVICE
A10: Interest | B10: INR Lakhs | C10: 0 | D10: 0 | E10: 0 | F10: 0 | G10: 741.23626 | H10: 730.94131 | I10: 720.64636 | J10: 710.35141 | K10: 700.05646 | L10: 689.76152 | M10: 679.46657 | N10: 669.17162 | O10: 658.87667 | P10: 648.58172 | Q10: 638.28678 | R10: 627.99183 | S10: 617.69688 | T10: 607.40193 | U10: 597.10698 | V10: 586.81204 | W10: 576.51709 | X10: 566.22214 | Y10: 555.92719 | Z10: 545.63224 | AA10: 535.3373 | AB10: 525.04235 | AC10: 514.7474 | AD10: 504.45245 | AE10: 494.1575 | AF10: 483.86256 | AG10: 473.56761 | AH10: 463.27266 | AI10: 452.97771 | AJ10: 442.68276 | AK10: 432.38782 | AL10: 422.09287 | AM10: 411.79792 | AN10: 401.50297 | AO10: 391.20802 | AP10: 380.91308 | AQ10: 370.61813 | AR10: 360.32318 | AS10: 350.02823 | AT10: 339.73328 | AU10: 329.43834 | AV10: 319.14339 | AW10: 308.84844 | AX10: 298.55349 | AY10: 288.25854 | AZ10: 277.9636 | BA10: 267.66865 | BB10: 257.3737 | BC10: 247.07875 | BD10: 236.7838 | BE10: 226.48886 | BF10: 216.19391 | BG10: 205.89896 | BH10: 195.60401 | BI10: 185.30906 | BJ10: 175.01412 | BK10: 164.71917 | BL10: 154.42422 | BM10: 144.12927 | BN10: 133.83432 | BO10: 123.53938 | BP10: 113.24443 | BQ10: 102.94948 | BR10: 92.654532 | BS10: 82.359584 | BT10: 72.064636 | BU10: 61.769688 | BV10: 51.47474 | BW10: 41.179792 | BX10: 30.884844 | BY10: 20.589896 | BZ10: 10.294948 | CA10: 0 | CB10: 0 | CC10: 0 | CD10: 0 | CE10: 0 | CF10: 0 | CG10: 0 | CH10: 0 | CI10: 0 | CJ10: 0 | CK10: 0 | CL10: 0 | CM10: 0 | CN10: 0 | CO10: 0 | CP10: 0 | CQ10: 0 | CR10: 0 | CS10: 0 | CT10: 0 | CU10: 0 | CV10: 0 | CW10: 0 | CX10: 0 | CY10: 0 | CZ10: 0 | DA10: 0 | DB10: 0
A11: Principal Repayment | B11: INR Lakhs | C11: 0 | D11: 0 | E11: 0 | F11: 0 | G11: 437.5 | H11: 437.5 | I11: 437.5 | J11: 437.5 | K11: 437.5 | L11: 437.5 | M11: 437.5 | N11: 437.5 | O11: 437.5 | P11: 437.5 | Q11: 437.5 | R11: 437.5 | S11: 437.5 | T11: 437.5 | U11: 437.5 | V11: 437.5 | W11: 437.5 | X11: 437.5 | Y11: 437.5 | Z11: 437.5 | AA11: 437.5 | AB11: 437.5 | AC11: 437.5 | AD11: 437.5 | AE11: 437.5 | AF11: 437.5 | AG11: 437.5 | AH11: 437.5 | AI11: 437.5 | AJ11: 437.5 | AK11: 437.5 | AL11: 437.5 | AM11: 437.5 | AN11: 437.5 | AO11: 437.5 | AP11: 437.5 | AQ11: 437.5 | AR11: 437.5 | AS11: 437.5 | AT11: 437.5 | AU11: 437.5 | AV11: 437.5 | AW11: 437.5 | AX11: 437.5 | AY11: 437.5 | AZ11: 437.5 | BA11: 437.5 | BB11: 437.5 | BC11: 437.5 | BD11: 437.5 | BE11: 437.5 | BF11: 437.5 | BG11: 437.5 | BH11: 437.5 | BI11: 437.5 | BJ11: 437.5 | BK11: 437.5 | BL11: 437.5 | BM11: 437.5 | BN11: 437.5 | BO11: 437.5 | BP11: 437.5 | BQ11: 437.5 | BR11: 437.5 | BS11: 437.5 | BT11: 437.5 | BU11: 437.5 | BV11: 437.5 | BW11: 437.5 | BX11: 437.5 | BY11: 437.5 | BZ11: 437.5 | CA11: 0 | CB11: 0 | CC11: 0 | CD11: 0 | CE11: 0 | CF11: 0 | CG11: 0 | CH11: 0 | CI11: 0 | CJ11: 0 | CK11: 0 | CL11: 0 | CM11: 0 | CN11: 0 | CO11: 0 | CP11: 0 | CQ11: 0 | CR11: 0 | CS11: 0 | CT11: 0 | CU11: 0 | CV11: 0 | CW11: 0 | CX11: 0 | CY11: 0 | CZ11: 0 | DA11: 0 | DB11: 0
A12: Total Debt Service | B12: INR Lakhs | C12: 0 | D12: 0 | E12: 0 | F12: 0 | G12: 1178.7363 | H12: 1168.4413 | I12: 1158.1464 | J12: 1147.8514 | K12: 1137.5565 | L12: 1127.2615 | M12: 1116.9666 | N12: 1106.6716 | O12: 1096.3767 | P12: 1086.0817 | Q12: 1075.7868 | R12: 1065.4918 | S12: 1055.1969 | T12: 1044.9019 | U12: 1034.607 | V12: 1024.312 | W12: 1014.0171 | X12: 1003.7221 | Y12: 993.42719 | Z12: 983.13224 | AA12: 972.8373 | AB12: 962.54235 | AC12: 952.2474 | AD12: 941.95245 | AE12: 931.6575 | AF12: 921.36256 | AG12: 911.06761 | AH12: 900.77266 | AI12: 890.47771 | AJ12: 880.18276 | AK12: 869.88782 | AL12: 859.59287 | AM12: 849.29792 | AN12: 839.00297 | AO12: 828.70802 | AP12: 818.41308 | AQ12: 808.11813 | AR12: 797.82318 | AS12: 787.52823 | AT12: 777.23328 | AU12: 766.93834 | AV12: 756.64339 | AW12: 746.34844 | AX12: 736.05349 | AY12: 725.75854 | AZ12: 715.4636 | BA12: 705.16865 | BB12: 694.8737 | BC12: 684.57875 | BD12: 674.2838 | BE12: 663.98886 | BF12: 653.69391 | BG12: 643.39896 | BH12: 633.10401 | BI12: 622.80906 | BJ12: 612.51412 | BK12: 602.21917 | BL12: 591.92422 | BM12: 581.62927 | BN12: 571.33432 | BO12: 561.03938 | BP12: 550.74443 | BQ12: 540.44948 | BR12: 530.15453 | BS12: 519.85958 | BT12: 509.56464 | BU12: 499.26969 | BV12: 488.97474 | BW12: 478.67979 | BX12: 468.38484 | BY12: 458.0899 | BZ12: 447.79495 | CA12: 0 | CB12: 0 | CC12: 0 | CD12: 0 | CE12: 0 | CF12: 0 | CG12: 0 | CH12: 0 | CI12: 0 | CJ12: 0 | CK12: 0 | CL12: 0 | CM12: 0 | CN12: 0 | CO12: 0 | CP12: 0 | CQ12: 0 | CR12: 0 | CS12: 0 | CT12: 0 | CU12: 0 | CV12: 0 | CW12: 0 | CX12: 0 | CY12: 0 | CZ12: 0 | DA12: 0 | DB12: 0
A13: DSCR | B13: x | G13: 0.84987987 | H13: 0.85470556 | I13: 0.85960898 | J13: 0.86459212 | K13: 0.86965709 | L13: 0.87480605 | M13: 0.88004124 | N13: 0.88536498 | O13: 0.8907797 | P13: 0.89628788 | Q13: 0.90189214 | R13: 0.90759517 | S13: 0.91339977 | T13: 0.91930886 | U13: 0.92532547 | V13: 0.93145274 | W13: 0.93769395 | X13: 0.94405252 | Y13: 0.950532 | Z13: 0.95713608 | AA13: 0.96386861 | AB13: 0.97073363 | AC13: 0.97773532 | AD13: 0.98487806 | AE13: 0.99216641 | AF13: 0.99960515 | AG13: 1.0071993 | AH13: 1.014954 | AI13: 1.0228747 | AJ13: 1.0309672 | AK13: 1.0392374 | AL13: 1.0476916 | AM13: 1.0563363 | AN13: 1.0651785 | AO13: 1.0742254 | AP13: 1.0834845 | AQ13: 1.0929638 | AR13: 1.1026718 | AS13: 1.1126172 | AT13: 1.1228093 | AU13: 1.131522 | AV13: 1.1399882 | AW13: 1.1486747 | AX13: 1.1575904 | AY13: 1.166745 | AZ13: 1.1761488 | BA13: 1.1858124 | BB13: 1.1957473 | BC13: 1.2059657 | BD13: 1.2164803 | BE13: 1.2273048 | BF13: 1.2384537 | BG13: 1.2499425 | BH13: 1.2617875 | BI13: 1.2740064 | BJ13: 1.2866177 | BK13: 1.2996415 | BL13: 1.3130991 | BM13: 1.3270133 | BN13: 1.3414088 | BO13: 1.3563118 | BP13: 1.3717506 | BQ13: 1.3877556 | BR13: 1.4043596 | BS13: 1.4215981 | BT13: 1.4395092 | BU13: 1.4581345 | BV13: 1.4775187 | BW13: 1.4977106 | BX13: 1.5187634 | BY13: 1.5407347 | BZ13: 1.5636876
A15: FREE & EQUITY CASHFLOWS
A16: Free Cashflow (post-DS) | B16: INR Lakhs | C16: 0 | D16: 0 | E16: 0 | F16: 0 | G16: -176.95204 | H16: -169.76802 | I16: -162.59335 | J16: -155.42812 | K16: -148.27242 | L16: -141.12632 | M16: -133.98993 | N16: -126.86332 | O16: -119.74659 | P16: -112.63984 | Q16: -105.54314 | R16: -98.456593 | S16: -91.380292 | T16: -84.314327 | U16: -77.258793 | V16: -70.213784 | W16: -63.179394 | X16: -56.155721 | Y16: -49.142859 | Z16: -42.140906 | AA16: -35.149959 | AB16: -28.170118 | AC16: -21.201481 | AD16: -14.244148 | AE16: -7.2982201 | AF16: -0.3637979 | AG16: 6.5590162 | AH16: 13.47012 | AI16: 20.369408 | AJ16: 27.256779 | AK16: 34.132126 | AL16: 40.995343 | AM16: 47.846324 | AN16: 54.684962 | AO16: 61.511149 | AP16: 68.324776 | AQ16: 75.125733 | AR16: 81.913909 | AS16: 88.689194 | AT16: 95.451476 | AU16: 100.86923 | AV16: 105.92118 | AW16: 110.96312 | AX16: 115.99497 | AY16: 121.01664 | AZ16: 126.02803 | BA16: 131.02907 | BB16: 136.01966 | BC16: 140.99972 | BD16: 145.96914 | BE16: 150.92785 | BF16: 155.87575 | BG16: 160.81275 | BH16: 165.73875 | BI16: 170.65366 | BJ16: 175.55739 | BK16: 180.44984 | BL16: 185.33092 | BM16: 190.20052 | BN16: 195.05856 | BO16: 199.90494 | BP16: 204.73955 | BQ16: 209.5623 | BR16: 214.37309 | BS16: 219.17181 | BT16: 223.95837 | BU16: 228.73266 | BV16: 233.49458 | BW16: 238.24403 | BX16: 242.9809 | BY16: 247.70508 | BZ16: 252.41648 | CA16: 694.61498 | CB16: 691.57927 | CC16: 688.53045 | CD16: 685.46841 | CE16: 682.39303 | CF16: 679.30422 | CG16: 676.20185 | CH16: 673.08582 | CI16: 669.95602 | CJ16: 666.81232 | CK16: 663.65461 | CL16: 660.48279 | CM16: 657.29672 | CN16: 654.0963 | CO16: 650.88141 | CP16: 647.65192 | CQ16: 644.40773 | CR16: 641.1487 | CS16: 637.87471 | CT16: 634.58565 | CU16: 631.28139 | CV16: 627.9618 | CW16: 624.62677 | CX16: 621.27616 | CY16: 617.90984 | CZ16: 614.5277 | DA16: 611.1296 | DB16: 607.7154
A17: DSRA Funding | B17: INR Lakhs | C17: 0 | D17: 0 | E17: 0 | F17: 0 | G17: 0 | H17: 0 | I17: 0 | J17: 0 | K17: 0 | L17: 0 | M17: 0 | N17: 0 | O17: 0 | P17: 0 | Q17: 0 | R17: 0 | S17: 0 | T17: 0 | U17: 0 | V17: 0 | W17: 0 | X17: 0 | Y17: 0 | Z17: 0 | AA17: 0 | AB17: 0 | AC17: 0 | AD17: 0 | AE17: 0 | AF17: 0 | AG17: 0 | AH17: 0 | AI17: 0 | AJ17: 0 | AK17: 0 | AL17: 0 | AM17: 0 | AN17: 0 | AO17: 0 | AP17: 0 | AQ17: 0 | AR17: 0 | AS17: 0 | AT17: 0 | AU17: 0 | AV17: 0 | AW17: 0 | AX17: 0 | AY17: 0 | AZ17: 0 | BA17: 0 | BB17: 0 | BC17: 0 | BD17: 0 | BE17: 0 | BF17: 0 | BG17: 0 | BH17: 0 | BI17: 0 | BJ17: 0 | BK17: 0 | BL17: 0 | BM17: 0 | BN17: 0 | BO17: 0 | BP17: 0 | BQ17: 0 | BR17: 0 | BS17: 0 | BT17: 0 | BU17: 0 | BV17: 0 | BW17: 0 | BX17: 0 | BY17: 0 | BZ17: 0 | CA17: 0 | CB17: 0 | CC17: 0 | CD17: 0 | CE17: 0 | CF17: 0 | CG17: 0 | CH17: 0 | CI17: 0 | CJ17: 0 | CK17: 0 | CL17: 0 | CM17: 0 | CN17: 0 | CO17: 0 | CP17: 0 | CQ17: 0 | CR17: 0 | CS17: 0 | CT17: 0 | CU17: 0 | CV17: 0 | CW17: 0 | CX17: 0 | CY17: 0 | CZ17: 0 | DA17: 0 | DB17: 0
A18: Cash Sweep | B18: INR Lakhs | C18: 0 | D18: 0 | E18: 0 | F18: 0 | G18: 0 | H18: 0 | I18: 0 | J18: 0 | K18: 0 | L18: 0 | M18: 0 | N18: 0 | O18: 0 | P18: 0 | Q18: 0 | R18: 0 | S18: 0 | T18: 0 | U18: 0 | V18: 0 | W18: 0 | X18: 0 | Y18: 0 | Z18: 0 | AA18: 0 | AB18: 0 | AC18: 0 | AD18: 0 | AE18: 0 | AF18: 0 | AG18: 0 | AH18: 0 | AI18: 0 | AJ18: 0 | AK18: 0 | AL18: 0 | AM18: 0 | AN18: 0 | AO18: 0 | AP18: 0 | AQ18: 0 | AR18: 0 | AS18: 0 | AT18: 0 | AU18: 0 | AV18: 0 | AW18: 0 | AX18: 0 | AY18: 0 | AZ18: 0 | BA18: 0 | BB18: 0 | BC18: 0 | BD18: 0 | BE18: 0 | BF18: 0 | BG18: 0 | BH18: 0 | BI18: 0 | BJ18: 0 | BK18: 0 | BL18: 0 | BM18: 0 | BN18: 0 | BO18: 0 | BP18: 0 | BQ18: 0 | BR18: 0 | BS18: 0 | BT18: 0 | BU18: 0 | BV18: 0 | BW18: 0 | BX18: 0 | BY18: 0 | BZ18: 0 | CA18: 0 | CB18: 0 | CC18: 0 | CD18: 0 | CE18: 0 | CF18: 0 | CG18: 0 | CH18: 0 | CI18: 0 | CJ18: 0 | CK18: 0 | CL18: 0 | CM18: 0 | CN18: 0 | CO18: 0 | CP18: 0 | CQ18: 0 | CR18: 0 | CS18: 0 | CT18: 0 | CU18: 0 | CV18: 0 | CW18: 0 | CX18: 0 | CY18: 0 | CZ18: 0 | DA18: 0 | DB18: 0
A19: Equity Distribution | B19: INR Lakhs | C19: 0 | D19: 0 | E19: 0 | F19: 0 | G19: 0 | H19: 0 | I19: 0 | J19: 0 | K19: 0 | L19: 0 | M19: 0 | N19: 0 | O19: 0 | P19: 0 | Q19: 0 | R19: 0 | S19: 0 | T19: 0 | U19: 0 | V19: 0 | W19: 0 | X19: 0 | Y19: 0 | Z19: 0 | AA19: 0 | AB19: 0 | AC19: 0 | AD19: 0 | AE19: 0 | AF19: 0 | AG19: 6.5590162 | AH19: 13.47012 | AI19: 20.369408 | AJ19: 27.256779 | AK19: 34.132126 | AL19: 40.995343 | AM19: 47.846324 | AN19: 54.684962 | AO19: 61.511149 | AP19: 68.324776 | AQ19: 75.125733 | AR19: 81.913909 | AS19: 88.689194 | AT19: 95.451476 | AU19: 100.86923 | AV19: 105.92118 | AW19: 110.96312 | AX19: 115.99497 | AY19: 121.01664 | AZ19: 126.02803 | BA19: 131.02907 | BB19: 136.01966 | BC19: 140.99972 | BD19: 145.96914 | BE19: 150.92785 | BF19: 155.87575 | BG19: 160.81275 | BH19: 165.73875 | BI19: 170.65366 | BJ19: 175.55739 | BK19: 180.44984 | BL19: 185.33092 | BM19: 190.20052 | BN19: 195.05856 | BO19: 199.90494 | BP19: 204.73955 | BQ19: 209.5623 | BR19: 214.37309 | BS19: 219.17181 | BT19: 223.95837 | BU19: 228.73266 | BV19: 233.49458 | BW19: 238.24403 | BX19: 242.9809 | BY19: 247.70508 | BZ19: 252.41648 | CA19: 694.61498 | CB19: 691.57927 | CC19: 688.53045 | CD19: 685.46841 | CE19: 682.39303 | CF19: 679.30422 | CG19: 676.20185 | CH19: 673.08582 | CI19: 669.95602 | CJ19: 666.81232 | CK19: 663.65461 | CL19: 660.48279 | CM19: 657.29672 | CN19: 654.0963 | CO19: 650.88141 | CP19: 647.65192 | CQ19: 644.40773 | CR19: 641.1487 | CS19: 637.87471 | CT19: 634.58565 | CU19: 631.28139 | CV19: 627.9618 | CW19: 624.62677 | CX19: 621.27616 | CY19: 617.90984 | CZ19: 614.5277 | DA19: 611.1296 | DB19: 607.7154
A21: IRR CASHFLOWS
A22: Equity Invested (−ve) | B22: INR Lakhs | C22: -3375 | D22: -3566.9531 | E22: -3758.9063 | F22: -3950.8594 | G22: 0 | H22: 0 | I22: 0 | J22: 0 | K22: 0 | L22: 0 | M22: 0 | N22: 0 | O22: 0 | P22: 0 | Q22: 0 | R22: 0 | S22: 0 | T22: 0 | U22: 0 | V22: 0 | W22: 0 | X22: 0 | Y22: 0 | Z22: 0 | AA22: 0 | AB22: 0 | AC22: 0 | AD22: 0 | AE22: 0 | AF22: 0 | AG22: 0 | AH22: 0 | AI22: 0 | AJ22: 0 | AK22: 0 | AL22: 0 | AM22: 0 | AN22: 0 | AO22: 0 | AP22: 0 | AQ22: 0 | AR22: 0 | AS22: 0 | AT22: 0 | AU22: 0 | AV22: 0 | AW22: 0 | AX22: 0 | AY22: 0 | AZ22: 0 | BA22: 0 | BB22: 0 | BC22: 0 | BD22: 0 | BE22: 0 | BF22: 0 | BG22: 0 | BH22: 0 | BI22: 0 | BJ22: 0 | BK22: 0 | BL22: 0 | BM22: 0 | BN22: 0 | BO22: 0 | BP22: 0 | BQ22: 0 | BR22: 0 | BS22: 0 | BT22: 0 | BU22: 0 | BV22: 0 | BW22: 0 | BX22: 0 | BY22: 0 | BZ22: 0 | CA22: 0 | CB22: 0 | CC22: 0 | CD22: 0 | CE22: 0 | CF22: 0 | CG22: 0 | CH22: 0 | CI22: 0 | CJ22: 0 | CK22: 0 | CL22: 0 | CM22: 0 | CN22: 0 | CO22: 0 | CP22: 0 | CQ22: 0 | CR22: 0 | CS22: 0 | CT22: 0 | CU22: 0 | CV22: 0 | CW22: 0 | CX22: 0 | CY22: 0 | CZ22: 0 | DA22: 0 | DB22: 0
A23: Equity Cashflow | B23: INR Lakhs | C23: -3375 | D23: -3566.9531 | E23: -3758.9063 | F23: -3950.8594 | G23: 0 | H23: 0 | I23: 0 | J23: 0 | K23: 0 | L23: 0 | M23: 0 | N23: 0 | O23: 0 | P23: 0 | Q23: 0 | R23: 0 | S23: 0 | T23: 0 | U23: 0 | V23: 0 | W23: 0 | X23: 0 | Y23: 0 | Z23: 0 | AA23: 0 | AB23: 0 | AC23: 0 | AD23: 0 | AE23: 0 | AF23: 0 | AG23: 6.5590162 | AH23: 13.47012 | AI23: 20.369408 | AJ23: 27.256779 | AK23: 34.132126 | AL23: 40.995343 | AM23: 47.846324 | AN23: 54.684962 | AO23: 61.511149 | AP23: 68.324776 | AQ23: 75.125733 | AR23: 81.913909 | AS23: 88.689194 | AT23: 95.451476 | AU23: 100.86923 | AV23: 105.92118 | AW23: 110.96312 | AX23: 115.99497 | AY23: 121.01664 | AZ23: 126.02803 | BA23: 131.02907 | BB23: 136.01966 | BC23: 140.99972 | BD23: 145.96914 | BE23: 150.92785 | BF23: 155.87575 | BG23: 160.81275 | BH23: 165.73875 | BI23: 170.65366 | BJ23: 175.55739 | BK23: 180.44984 | BL23: 185.33092 | BM23: 190.20052 | BN23: 195.05856 | BO23: 199.90494 | BP23: 204.73955 | BQ23: 209.5623 | BR23: 214.37309 | BS23: 219.17181 | BT23: 223.95837 | BU23: 228.73266 | BV23: 233.49458 | BW23: 238.24403 | BX23: 242.9809 | BY23: 247.70508 | BZ23: 252.41648 | CA23: 694.61498 | CB23: 691.57927 | CC23: 688.53045 | CD23: 685.46841 | CE23: 682.39303 | CF23: 679.30422 | CG23: 676.20185 | CH23: 673.08582 | CI23: 669.95602 | CJ23: 666.81232 | CK23: 663.65461 | CL23: 660.48279 | CM23: 657.29672 | CN23: 654.0963 | CO23: 650.88141 | CP23: 647.65192 | CQ23: 644.40773 | CR23: 641.1487 | CS23: 637.87471 | CT23: 634.58565 | CU23: 631.28139 | CV23: 627.9618 | CW23: 624.62677 | CX23: 621.27616 | CY23: 617.90984 | CZ23: 614.5277 | DA23: 611.1296 | DB23: 607.7154
A24: Project Cashflow | B24: INR Lakhs | C24: -11250 | D24: -11250 | E24: -11250 | F24: -11250 | G24: 1001.7842 | H24: 998.67329 | I24: 995.55301 | J24: 992.42329 | K24: 989.28405 | L24: 986.13519 | M24: 982.97664 | N24: 979.8083 | O24: 976.63008 | P24: 973.44189 | Q24: 970.24364 | R24: 967.03523 | S24: 963.81659 | T24: 960.58761 | U24: 957.34819 | V24: 954.09825 | W24: 950.83769 | X24: 947.56642 | Y24: 944.28433 | Z24: 940.99134 | AA24: 937.68734 | AB24: 934.37223 | AC24: 931.04592 | AD24: 927.7083 | AE24: 924.35928 | AF24: 920.99876 | AG24: 917.62662 | AH24: 914.24278 | AI24: 910.84712 | AJ24: 907.43954 | AK24: 904.01994 | AL24: 900.58821 | AM24: 897.14424 | AN24: 893.68793 | AO24: 890.21917 | AP24: 886.73785 | AQ24: 883.24386 | AR24: 879.73709 | AS24: 876.21743 | AT24: 872.68476 | AU24: 867.80757 | AV24: 862.56457 | AW24: 857.31156 | AX24: 852.04846 | AY24: 846.77518 | AZ24: 841.49163 | BA24: 836.19772 | BB24: 830.89336 | BC24: 825.57847 | BD24: 820.25295 | BE24: 814.91671 | BF24: 809.56966 | BG24: 804.21171 | BH24: 798.84276 | BI24: 793.46272 | BJ24: 788.0715 | BK24: 782.66901 | BL24: 777.25514 | BM24: 771.8298 | BN24: 766.39289 | BO24: 760.94432 | BP24: 755.48398 | BQ24: 750.01178 | BR24: 744.52762 | BS24: 739.03139 | BT24: 733.523 | BU24: 728.00235 | BV24: 722.46932 | BW24: 716.92382 | BX24: 711.36574 | BY24: 705.79498 | BZ24: 700.21143 | CA24: 694.61498 | CB24: 691.57927 | CC24: 688.53045 | CD24: 685.46841 | CE24: 682.39303 | CF24: 679.30422 | CG24: 676.20185 | CH24: 673.08582 | CI24: 669.95602 | CJ24: 666.81232 | CK24: 663.65461 | CL24: 660.48279 | CM24: 657.29672 | CN24: 654.0963 | CO24: 650.88141 | CP24: 647.65192 | CQ24: 644.40773 | CR24: 641.1487 | CS24: 637.87471 | CT24: 634.58565 | CU24: 631.28139 | CV24: 627.9618 | CW24: 624.62677 | CX24: 621.27616 | CY24: 617.90984 | CZ24: 614.5277 | DA24: 611.1296 | DB24: 607.7154
A26: CONSTRUCTION FINANCING
A27: Capex Drawdown | B27: INR Lakhs | C27: 11250 | D27: 11250 | E27: 11250 | F27: 11250 | G27: 0 | H27: 0 | I27: 0 | J27: 0 | K27: 0 | L27: 0 | M27: 0 | N27: 0 | O27: 0 | P27: 0 | Q27: 0 | R27: 0 | S27: 0 | T27: 0 | U27: 0 | V27: 0 | W27: 0 | X27: 0 | Y27: 0 | Z27: 0 | AA27: 0 | AB27: 0 | AC27: 0 | AD27: 0 | AE27: 0 | AF27: 0 | AG27: 0 | AH27: 0 | AI27: 0 | AJ27: 0 | AK27: 0 | AL27: 0 | AM27: 0 | AN27: 0 | AO27: 0 | AP27: 0 | AQ27: 0 | AR27: 0 | AS27: 0 | AT27: 0 | AU27: 0 | AV27: 0 | AW27: 0 | AX27: 0 | AY27: 0 | AZ27: 0 | BA27: 0 | BB27: 0 | BC27: 0 | BD27: 0 | BE27: 0 | BF27: 0 | BG27: 0 | BH27: 0 | BI27: 0 | BJ27: 0 | BK27: 0 | BL27: 0 | BM27: 0 | BN27: 0 | BO27: 0 | BP27: 0 | BQ27: 0 | BR27: 0 | BS27: 0 | BT27: 0 | BU27: 0 | BV27: 0 | BW27: 0 | BX27: 0 | BY27: 0 | BZ27: 0 | CA27: 0 | CB27: 0 | CC27: 0 | CD27: 0 | CE27: 0 | CF27: 0 | CG27: 0 | CH27: 0 | CI27: 0 | CJ27: 0 | CK27: 0 | CL27: 0 | CM27: 0 | CN27: 0 | CO27: 0 | CP27: 0 | CQ27: 0 | CR27: 0 | CS27: 0 | CT27: 0 | CU27: 0 | CV27: 0 | CW27: 0 | CX27: 0 | CY27: 0 | CZ27: 0 | DA27: 0 | DB27: 0
A28: Debt Drawdown | B28: INR Lakhs | C28: 7875 | D28: 7875 | E28: 7875 | F28: 7875 | G28: 0 | H28: 0 | I28: 0 | J28: 0 | K28: 0 | L28: 0 | M28: 0 | N28: 0 | O28: 0 | P28: 0 | Q28: 0 | R28: 0 | S28: 0 | T28: 0 | U28: 0 | V28: 0 | W28: 0 | X28: 0 | Y28: 0 | Z28: 0 | AA28: 0 | AB28: 0 | AC28: 0 | AD28: 0 | AE28: 0 | AF28: 0 | AG28: 0 | AH28: 0 | AI28: 0 | AJ28: 0 | AK28: 0 | AL28: 0 | AM28: 0 | AN28: 0 | AO28: 0 | AP28: 0 | AQ28: 0 | AR28: 0 | AS28: 0 | AT28: 0 | AU28: 0 | AV28: 0 | AW28: 0 | AX28: 0 | AY28: 0 | AZ28: 0 | BA28: 0 | BB28: 0 | BC28: 0 | BD28: 0 | BE28: 0 | BF28: 0 | BG28: 0 | BH28: 0 | BI28: 0 | BJ28: 0 | BK28: 0 | BL28: 0 | BM28: 0 | BN28: 0 | BO28: 0 | BP28: 0 | BQ28: 0 | BR28: 0 | BS28: 0 | BT28: 0 | BU28: 0 | BV28: 0 | BW28: 0 | BX28: 0 | BY28: 0 | BZ28: 0 | CA28: 0 | CB28: 0 | CC28: 0 | CD28: 0 | CE28: 0 | CF28: 0 | CG28: 0 | CH28: 0 | CI28: 0 | CJ28: 0 | CK28: 0 | CL28: 0 | CM28: 0 | CN28: 0 | CO28: 0 | CP28: 0 | CQ28: 0 | CR28: 0 | CS28: 0 | CT28: 0 | CU28: 0 | CV28: 0 | CW28: 0 | CX28: 0 | CY28: 0 | CZ28: 0 | DA28: 0 | DB28: 0
A29: IDC (interest during construction) | B29: INR Lakhs | C29: 0 | D29: 191.95312 | E29: 383.90625 | F29: 575.85937 | G29: 0 | H29: 0 | I29: 0 | J29: 0 | K29: 0 | L29: 0 | M29: 0 | N29: 0 | O29: 0 | P29: 0 | Q29: 0 | R29: 0 | S29: 0 | T29: 0 | U29: 0 | V29: 0 | W29: 0 | X29: 0 | Y29: 0 | Z29: 0 | AA29: 0 | AB29: 0 | AC29: 0 | AD29: 0 | AE29: 0 | AF29: 0 | AG29: 0 | AH29: 0 | AI29: 0 | AJ29: 0 | AK29: 0 | AL29: 0 | AM29: 0 | AN29: 0 | AO29: 0 | AP29: 0 | AQ29: 0 | AR29: 0 | AS29: 0 | AT29: 0 | AU29: 0 | AV29: 0 | AW29: 0 | AX29: 0 | AY29: 0 | AZ29: 0 | BA29: 0 | BB29: 0 | BC29: 0 | BD29: 0 | BE29: 0 | BF29: 0 | BG29: 0 | BH29: 0 | BI29: 0 | BJ29: 0 | BK29: 0 | BL29: 0 | BM29: 0 | BN29: 0 | BO29: 0 | BP29: 0 | BQ29: 0 | BR29: 0 | BS29: 0 | BT29: 0 | BU29: 0 | BV29: 0 | BW29: 0 | BX29: 0 | BY29: 0 | BZ29: 0 | CA29: 0 | CB29: 0 | CC29: 0 | CD29: 0 | CE29: 0 | CF29: 0 | CG29: 0 | CH29: 0 | CI29: 0 | CJ29: 0 | CK29: 0 | CL29: 0 | CM29: 0 | CN29: 0 | CO29: 0 | CP29: 0 | CQ29: 0 | CR29: 0 | CS29: 0 | CT29: 0 | CU29: 0 | CV29: 0 | CW29: 0 | CX29: 0 | CY29: 0 | CZ29: 0 | DA29: 0 | DB29: 0
A30: Cumulative Capex | B30: INR Lakhs | C30: 11250 | D30: 22500 | E30: 33750 | F30: 45000 | G30: 45000 | H30: 45000 | I30: 45000 | J30: 45000 | K30: 45000 | L30: 45000 | M30: 45000 | N30: 45000 | O30: 45000 | P30: 45000 | Q30: 45000 | R30: 45000 | S30: 45000 | T30: 45000 | U30: 45000 | V30: 45000 | W30: 45000 | X30: 45000 | Y30: 45000 | Z30: 45000 | AA30: 45000 | AB30: 45000 | AC30: 45000 | AD30: 45000 | AE30: 45000 | AF30: 45000 | AG30: 45000 | AH30: 45000 | AI30: 45000 | AJ30: 45000 | AK30: 45000 | AL30: 45000 | AM30: 45000 | AN30: 45000 | AO30: 45000 | AP30: 45000 | AQ30: 45000 | AR30: 45000 | AS30: 45000 | AT30: 45000 | AU30: 45000 | AV30: 45000 | AW30: 45000 | AX30: 45000 | AY30: 45000 | AZ30: 45000 | BA30: 45000 | BB30: 45000 | BC30: 45000 | BD30: 45000 | BE30: 45000 | BF30: 45000 | BG30: 45000 | BH30: 45000 | BI30: 45000 | BJ30: 45000 | BK30: 45000 | BL30: 45000 | BM30: 45000 | BN30: 45000 | BO30: 45000 | BP30: 45000 | BQ30: 45000 | BR30: 45000 | BS30: 45000 | BT30: 45000 | BU30: 45000 | BV30: 45000 | BW30: 45000 | BX30: 45000 | BY30: 45000 | BZ30: 45000 | CA30: 45000 | CB30: 45000 | CC30: 45000 | CD30: 45000 | CE30: 45000 | CF30: 45000 | CG30: 45000 | CH30: 45000 | CI30: 45000 | CJ30: 45000 | CK30: 45000 | CL30: 45000 | CM30: 45000 | CN30: 45000 | CO30: 45000 | CP30: 45000 | CQ30: 45000 | CR30: 45000 | CS30: 45000 | CT30: 45000 | CU30: 45000 | CV30: 45000 | CW30: 45000 | CX30: 45000 | CY30: 45000 | CZ30: 45000 | DA30: 45000 | DB30: 45000

Sheet Debt Schedule
A1: DEBT SCHEDULE
